29-04-2025 13:46:20 | ERROR    | root:191 | Connection loop error
Traceback (most recent call last):
  File "/usr/lib/python3.12/asyncio/selector_events.py", line 988, in _read_ready__get_buffer
    nbytes = self._sock.recv_into(buf)
             ^^^^^^^^^^^^^^^^^^^^^^^^^
ConnectionResetError: [Errno 104] Connection reset by peer

The above exception was the direct cause of the following exception:

Traceback (most recent call last):
  File "/home/yoav/VSCode/Lip-C/server/handlers/connection.py", line 168, in handle_connection
    async for raw in ws:
  File "/home/yoav/VSCode/Lip-C/server/venv/lib/python3.12/site-packages/websockets/asyncio/connection.py", line 242, in __aiter__
    yield await self.recv()
          ^^^^^^^^^^^^^^^^^
  File "/home/yoav/VSCode/Lip-C/server/venv/lib/python3.12/site-packages/websockets/asyncio/connection.py", line 322, in recv
    raise self.protocol.close_exc from self.recv_exc
websockets.exceptions.ConnectionClosedError: no close frame received or sent
29-04-2025 13:46:21 | ERROR    | root:191 | Connection loop error
Traceback (most recent call last):
  File "/home/yoav/VSCode/Lip-C/server/handlers/connection.py", line 168, in handle_connection
    async for raw in ws:
  File "/home/yoav/VSCode/Lip-C/server/venv/lib/python3.12/site-packages/websockets/asyncio/connection.py", line 242, in __aiter__
    yield await self.recv()
          ^^^^^^^^^^^^^^^^^
  File "/home/yoav/VSCode/Lip-C/server/venv/lib/python3.12/site-packages/websockets/asyncio/connection.py", line 322, in recv
    raise self.protocol.close_exc from self.recv_exc
websockets.exceptions.ConnectionClosedError: no close frame received or sent
29-04-2025 13:47:27 | ERROR    | root:191 | Connection loop error
Traceback (most recent call last):
  File "/home/yoav/VSCode/Lip-C/server/handlers/connection.py", line 168, in handle_connection
    async for raw in ws:
  File "/home/yoav/VSCode/Lip-C/server/venv/lib/python3.12/site-packages/websockets/asyncio/connection.py", line 242, in __aiter__
    yield await self.recv()
          ^^^^^^^^^^^^^^^^^
  File "/home/yoav/VSCode/Lip-C/server/venv/lib/python3.12/site-packages/websockets/asyncio/connection.py", line 322, in recv
    raise self.protocol.close_exc from self.recv_exc
websockets.exceptions.ConnectionClosedError: no close frame received or sent
29-04-2025 13:47:30 | ERROR    | root:191 | Connection loop error
Traceback (most recent call last):
  File "/home/yoav/VSCode/Lip-C/server/handlers/connection.py", line 168, in handle_connection
    async for raw in ws:
  File "/home/yoav/VSCode/Lip-C/server/venv/lib/python3.12/site-packages/websockets/asyncio/connection.py", line 242, in __aiter__
    yield await self.recv()
          ^^^^^^^^^^^^^^^^^
  File "/home/yoav/VSCode/Lip-C/server/venv/lib/python3.12/site-packages/websockets/asyncio/connection.py", line 322, in recv
    raise self.protocol.close_exc from self.recv_exc
websockets.exceptions.ConnectionClosedError: no close frame received or sent
29-04-2025 13:48:42 | ERROR    | root:191 | Connection loop error
Traceback (most recent call last):
  File "/home/yoav/VSCode/Lip-C/server/handlers/connection.py", line 168, in handle_connection
    async for raw in ws:
  File "/home/yoav/VSCode/Lip-C/server/venv/lib/python3.12/site-packages/websockets/asyncio/connection.py", line 242, in __aiter__
    yield await self.recv()
          ^^^^^^^^^^^^^^^^^
  File "/home/yoav/VSCode/Lip-C/server/venv/lib/python3.12/site-packages/websockets/asyncio/connection.py", line 322, in recv
    raise self.protocol.close_exc from self.recv_exc
websockets.exceptions.ConnectionClosedError: no close frame received or sent
29-04-2025 13:48:43 | ERROR    | root:191 | Connection loop error
Traceback (most recent call last):
  File "/home/yoav/VSCode/Lip-C/server/handlers/connection.py", line 168, in handle_connection
    async for raw in ws:
  File "/home/yoav/VSCode/Lip-C/server/venv/lib/python3.12/site-packages/websockets/asyncio/connection.py", line 242, in __aiter__
    yield await self.recv()
          ^^^^^^^^^^^^^^^^^
  File "/home/yoav/VSCode/Lip-C/server/venv/lib/python3.12/site-packages/websockets/asyncio/connection.py", line 322, in recv
    raise self.protocol.close_exc from self.recv_exc
websockets.exceptions.ConnectionClosedError: no close frame received or sent
29-04-2025 13:49:45 | ERROR    | root:191 | Connection loop error
Traceback (most recent call last):
  File "/home/yoav/VSCode/Lip-C/server/handlers/connection.py", line 168, in handle_connection
    async for raw in ws:
  File "/home/yoav/VSCode/Lip-C/server/venv/lib/python3.12/site-packages/websockets/asyncio/connection.py", line 242, in __aiter__
    yield await self.recv()
          ^^^^^^^^^^^^^^^^^
  File "/home/yoav/VSCode/Lip-C/server/venv/lib/python3.12/site-packages/websockets/asyncio/connection.py", line 322, in recv
    raise self.protocol.close_exc from self.recv_exc
websockets.exceptions.ConnectionClosedError: no close frame received or sent
29-04-2025 13:49:50 | ERROR    | root:191 | Connection loop error
Traceback (most recent call last):
  File "/home/yoav/VSCode/Lip-C/server/handlers/connection.py", line 168, in handle_connection
    async for raw in ws:
  File "/home/yoav/VSCode/Lip-C/server/venv/lib/python3.12/site-packages/websockets/asyncio/connection.py", line 242, in __aiter__
    yield await self.recv()
          ^^^^^^^^^^^^^^^^^
  File "/home/yoav/VSCode/Lip-C/server/venv/lib/python3.12/site-packages/websockets/asyncio/connection.py", line 322, in recv
    raise self.protocol.close_exc from self.recv_exc
websockets.exceptions.ConnectionClosedError: no close frame received or sent
29-04-2025 13:50:53 | ERROR    | root:191 | Connection loop error
Traceback (most recent call last):
  File "/home/yoav/VSCode/Lip-C/server/handlers/connection.py", line 168, in handle_connection
    async for raw in ws:
  File "/home/yoav/VSCode/Lip-C/server/venv/lib/python3.12/site-packages/websockets/asyncio/connection.py", line 242, in __aiter__
    yield await self.recv()
          ^^^^^^^^^^^^^^^^^
  File "/home/yoav/VSCode/Lip-C/server/venv/lib/python3.12/site-packages/websockets/asyncio/connection.py", line 322, in recv
    raise self.protocol.close_exc from self.recv_exc
websockets.exceptions.ConnectionClosedError: no close frame received or sent
29-04-2025 13:50:54 | ERROR    | root:191 | Connection loop error
Traceback (most recent call last):
  File "/home/yoav/VSCode/Lip-C/server/handlers/connection.py", line 168, in handle_connection
    async for raw in ws:
  File "/home/yoav/VSCode/Lip-C/server/venv/lib/python3.12/site-packages/websockets/asyncio/connection.py", line 242, in __aiter__
    yield await self.recv()
          ^^^^^^^^^^^^^^^^^
  File "/home/yoav/VSCode/Lip-C/server/venv/lib/python3.12/site-packages/websockets/asyncio/connection.py", line 322, in recv
    raise self.protocol.close_exc from self.recv_exc
websockets.exceptions.ConnectionClosedError: no close frame received or sent
29-04-2025 13:52:14 | ERROR    | root:191 | Connection loop error
Traceback (most recent call last):
  File "/usr/lib/python3.12/asyncio/selector_events.py", line 988, in _read_ready__get_buffer
    nbytes = self._sock.recv_into(buf)
             ^^^^^^^^^^^^^^^^^^^^^^^^^
ConnectionResetError: [Errno 104] Connection reset by peer

The above exception was the direct cause of the following exception:

Traceback (most recent call last):
  File "/home/yoav/VSCode/Lip-C/server/handlers/connection.py", line 168, in handle_connection
    async for raw in ws:
  File "/home/yoav/VSCode/Lip-C/server/venv/lib/python3.12/site-packages/websockets/asyncio/connection.py", line 242, in __aiter__
    yield await self.recv()
          ^^^^^^^^^^^^^^^^^
  File "/home/yoav/VSCode/Lip-C/server/venv/lib/python3.12/site-packages/websockets/asyncio/connection.py", line 322, in recv
    raise self.protocol.close_exc from self.recv_exc
websockets.exceptions.ConnectionClosedError: no close frame received or sent
29-04-2025 13:57:36 | ERROR    | root:163 | Handshake failed
Traceback (most recent call last):
  File "/home/yoav/VSCode/Lip-C/server/handlers/connection.py", line 161, in handle_connection
    aes_key = await _perform_handshake(ws)
              ^^^^^^^^^^^^^^^^^^^^^^^^^^^^
  File "/home/yoav/VSCode/Lip-C/server/handlers/connection.py", line 77, in _perform_handshake
    raise ValueError("Invalid handshake response")
ValueError: Invalid handshake response
29-04-2025 13:57:36 | ERROR    | websockets.server:378 | connection handler failed
Traceback (most recent call last):
  File "/home/yoav/VSCode/Lip-C/server/venv/lib/python3.12/site-packages/websockets/asyncio/server.py", line 376, in conn_handler
    await self.handler(connection)
  File "/home/yoav/VSCode/Lip-C/server/handlers/connection.py", line 164, in handle_connection
    await ws.send(json.dumps({"error": "Handshake failed"}))
  File "/home/yoav/VSCode/Lip-C/server/venv/lib/python3.12/site-packages/websockets/asyncio/connection.py", line 476, in send
    async with self.send_context():
  File "/usr/lib/python3.12/contextlib.py", line 210, in __aenter__
    return await anext(self.gen)
           ^^^^^^^^^^^^^^^^^^^^^
  File "/home/yoav/VSCode/Lip-C/server/venv/lib/python3.12/site-packages/websockets/asyncio/connection.py", line 957, in send_context
    raise self.protocol.close_exc from original_exc
websockets.exceptions.ConnectionClosedOK: received 1000 (OK); then sent 1000 (OK)
29-04-2025 14:05:48 | ERROR    | root:191 | Connection loop error
Traceback (most recent call last):
  File "/usr/lib/python3.12/asyncio/selector_events.py", line 988, in _read_ready__get_buffer
    nbytes = self._sock.recv_into(buf)
             ^^^^^^^^^^^^^^^^^^^^^^^^^
ConnectionResetError: [Errno 104] Connection reset by peer

The above exception was the direct cause of the following exception:

Traceback (most recent call last):
  File "/home/yoav/VSCode/Lip-C/server/handlers/connection.py", line 168, in handle_connection
    async for raw in ws:
  File "/home/yoav/VSCode/Lip-C/server/venv/lib/python3.12/site-packages/websockets/asyncio/connection.py", line 242, in __aiter__
    yield await self.recv()
          ^^^^^^^^^^^^^^^^^
  File "/home/yoav/VSCode/Lip-C/server/venv/lib/python3.12/site-packages/websockets/asyncio/connection.py", line 322, in recv
    raise self.protocol.close_exc from self.recv_exc
websockets.exceptions.ConnectionClosedError: no close frame received or sent
29-04-2025 14:07:09 | ERROR    | root:191 | Connection loop error
Traceback (most recent call last):
  File "/usr/lib/python3.12/asyncio/selector_events.py", line 988, in _read_ready__get_buffer
    nbytes = self._sock.recv_into(buf)
             ^^^^^^^^^^^^^^^^^^^^^^^^^
ConnectionResetError: [Errno 104] Connection reset by peer

The above exception was the direct cause of the following exception:

Traceback (most recent call last):
  File "/home/yoav/VSCode/Lip-C/server/handlers/connection.py", line 168, in handle_connection
    async for raw in ws:
  File "/home/yoav/VSCode/Lip-C/server/venv/lib/python3.12/site-packages/websockets/asyncio/connection.py", line 242, in __aiter__
    yield await self.recv()
          ^^^^^^^^^^^^^^^^^
  File "/home/yoav/VSCode/Lip-C/server/venv/lib/python3.12/site-packages/websockets/asyncio/connection.py", line 322, in recv
    raise self.protocol.close_exc from self.recv_exc
websockets.exceptions.ConnectionClosedError: no close frame received or sent
29-04-2025 14:30:10 | ERROR    | root:191 | Connection loop error
Traceback (most recent call last):
  File "/home/yoav/VSCode/Lip-C/server/handlers/connection.py", line 168, in handle_connection
    async for raw in ws:
  File "/home/yoav/VSCode/Lip-C/server/venv/lib/python3.12/site-packages/websockets/asyncio/connection.py", line 242, in __aiter__
    yield await self.recv()
          ^^^^^^^^^^^^^^^^^
  File "/home/yoav/VSCode/Lip-C/server/venv/lib/python3.12/site-packages/websockets/asyncio/connection.py", line 322, in recv
    raise self.protocol.close_exc from self.recv_exc
websockets.exceptions.ConnectionClosedError: no close frame received or sent
29-04-2025 14:33:02 | ERROR    | root:78 | Error receiving video frame: 
29-04-2025 14:33:03 | ERROR    | root:109 | Error receiving audio frame: 
29-04-2025 14:33:29 | ERROR    | root:109 | Error receiving audio frame: 
29-04-2025 14:33:30 | ERROR    | root:78 | Error receiving video frame: 
29-04-2025 14:33:57 | ERROR    | root:191 | Connection loop error
Traceback (most recent call last):
  File "/usr/lib/python3.12/asyncio/selector_events.py", line 988, in _read_ready__get_buffer
    nbytes = self._sock.recv_into(buf)
             ^^^^^^^^^^^^^^^^^^^^^^^^^
ConnectionResetError: [Errno 104] Connection reset by peer

The above exception was the direct cause of the following exception:

Traceback (most recent call last):
  File "/home/yoav/VSCode/Lip-C/server/handlers/connection.py", line 168, in handle_connection
    async for raw in ws:
  File "/home/yoav/VSCode/Lip-C/server/venv/lib/python3.12/site-packages/websockets/asyncio/connection.py", line 242, in __aiter__
    yield await self.recv()
          ^^^^^^^^^^^^^^^^^
  File "/home/yoav/VSCode/Lip-C/server/venv/lib/python3.12/site-packages/websockets/asyncio/connection.py", line 322, in recv
    raise self.protocol.close_exc from self.recv_exc
websockets.exceptions.ConnectionClosedError: no close frame received or sent
29-04-2025 14:33:58 | ERROR    | root:191 | Connection loop error
Traceback (most recent call last):
  File "/home/yoav/VSCode/Lip-C/server/handlers/connection.py", line 168, in handle_connection
    async for raw in ws:
  File "/home/yoav/VSCode/Lip-C/server/venv/lib/python3.12/site-packages/websockets/asyncio/connection.py", line 242, in __aiter__
    yield await self.recv()
          ^^^^^^^^^^^^^^^^^
  File "/home/yoav/VSCode/Lip-C/server/venv/lib/python3.12/site-packages/websockets/asyncio/connection.py", line 322, in recv
    raise self.protocol.close_exc from self.recv_exc
websockets.exceptions.ConnectionClosedError: no close frame received or sent
30-04-2025 14:37:27 | ERROR    | root:191 | Connection loop error
Traceback (most recent call last):
  File "/home/yoav/VSCode/Lip-C/server/handlers/connection.py", line 168, in handle_connection
    async for raw in ws:
  File "/home/yoav/VSCode/Lip-C/server/venv/lib/python3.12/site-packages/websockets/asyncio/connection.py", line 242, in __aiter__
    yield await self.recv()
          ^^^^^^^^^^^^^^^^^
  File "/home/yoav/VSCode/Lip-C/server/venv/lib/python3.12/site-packages/websockets/asyncio/connection.py", line 322, in recv
    raise self.protocol.close_exc from self.recv_exc
websockets.exceptions.ConnectionClosedError: no close frame received or sent
30-04-2025 18:06:33 | ERROR    | root:191 | Connection loop error
Traceback (most recent call last):
  File "/usr/lib/python3.12/asyncio/selector_events.py", line 988, in _read_ready__get_buffer
    nbytes = self._sock.recv_into(buf)
             ^^^^^^^^^^^^^^^^^^^^^^^^^
ConnectionResetError: [Errno 104] Connection reset by peer

The above exception was the direct cause of the following exception:

Traceback (most recent call last):
  File "/home/yoav/VSCode/Lip-C/server/handlers/connection.py", line 168, in handle_connection
    async for raw in ws:
  File "/home/yoav/VSCode/Lip-C/server/venv/lib/python3.12/site-packages/websockets/asyncio/connection.py", line 242, in __aiter__
    yield await self.recv()
          ^^^^^^^^^^^^^^^^^
  File "/home/yoav/VSCode/Lip-C/server/venv/lib/python3.12/site-packages/websockets/asyncio/connection.py", line 322, in recv
    raise self.protocol.close_exc from self.recv_exc
websockets.exceptions.ConnectionClosedError: no close frame received or sent
30-04-2025 18:15:42 | ERROR    | root:78 | Error receiving video frame: 
30-04-2025 18:15:43 | ERROR    | root:78 | Error receiving video frame: 
30-04-2025 18:19:11 | ERROR    | root:191 | Connection loop error
Traceback (most recent call last):
  File "/usr/lib/python3.12/asyncio/selector_events.py", line 988, in _read_ready__get_buffer
    nbytes = self._sock.recv_into(buf)
             ^^^^^^^^^^^^^^^^^^^^^^^^^
ConnectionResetError: [Errno 104] Connection reset by peer

The above exception was the direct cause of the following exception:

Traceback (most recent call last):
  File "/home/yoav/VSCode/Lip-C/server/handlers/connection.py", line 168, in handle_connection
    async for raw in ws:
  File "/home/yoav/VSCode/Lip-C/server/venv/lib/python3.12/site-packages/websockets/asyncio/connection.py", line 242, in __aiter__
    yield await self.recv()
          ^^^^^^^^^^^^^^^^^
  File "/home/yoav/VSCode/Lip-C/server/venv/lib/python3.12/site-packages/websockets/asyncio/connection.py", line 322, in recv
    raise self.protocol.close_exc from self.recv_exc
websockets.exceptions.ConnectionClosedError: no close frame received or sent
30-04-2025 18:19:12 | ERROR    | root:191 | Connection loop error
Traceback (most recent call last):
  File "/home/yoav/VSCode/Lip-C/server/handlers/connection.py", line 168, in handle_connection
    async for raw in ws:
  File "/home/yoav/VSCode/Lip-C/server/venv/lib/python3.12/site-packages/websockets/asyncio/connection.py", line 242, in __aiter__
    yield await self.recv()
          ^^^^^^^^^^^^^^^^^
  File "/home/yoav/VSCode/Lip-C/server/venv/lib/python3.12/site-packages/websockets/asyncio/connection.py", line 322, in recv
    raise self.protocol.close_exc from self.recv_exc
websockets.exceptions.ConnectionClosedError: no close frame received or sent
30-04-2025 18:21:32 | ERROR    | root:191 | Connection loop error
Traceback (most recent call last):
  File "/usr/lib/python3.12/asyncio/selector_events.py", line 988, in _read_ready__get_buffer
    nbytes = self._sock.recv_into(buf)
             ^^^^^^^^^^^^^^^^^^^^^^^^^
ConnectionResetError: [Errno 104] Connection reset by peer

The above exception was the direct cause of the following exception:

Traceback (most recent call last):
  File "/home/yoav/VSCode/Lip-C/server/handlers/connection.py", line 168, in handle_connection
    async for raw in ws:
  File "/home/yoav/VSCode/Lip-C/server/venv/lib/python3.12/site-packages/websockets/asyncio/connection.py", line 242, in __aiter__
    yield await self.recv()
          ^^^^^^^^^^^^^^^^^
  File "/home/yoav/VSCode/Lip-C/server/venv/lib/python3.12/site-packages/websockets/asyncio/connection.py", line 322, in recv
    raise self.protocol.close_exc from self.recv_exc
websockets.exceptions.ConnectionClosedError: no close frame received or sent
01-05-2025 11:11:22 | ERROR    | handlers.connection:193 | Connection loop error
Traceback (most recent call last):
  File "/usr/lib/python3.12/asyncio/selector_events.py", line 988, in _read_ready__get_buffer
    nbytes = self._sock.recv_into(buf)
             ^^^^^^^^^^^^^^^^^^^^^^^^^
ConnectionResetError: [Errno 104] Connection reset by peer

The above exception was the direct cause of the following exception:

Traceback (most recent call last):
  File "/home/yoav/VSCode/Lip-C/server/handlers/connection.py", line 170, in handle_connection
    async for raw in ws:
  File "/home/yoav/VSCode/Lip-C/server/venv/lib/python3.12/site-packages/websockets/asyncio/connection.py", line 242, in __aiter__
    yield await self.recv()
          ^^^^^^^^^^^^^^^^^
  File "/home/yoav/VSCode/Lip-C/server/venv/lib/python3.12/site-packages/websockets/asyncio/connection.py", line 322, in recv
    raise self.protocol.close_exc from self.recv_exc
websockets.exceptions.ConnectionClosedError: no close frame received or sent
